<robot name="onshape">
<material name="white">
		<color rgba="1 1 1 1"/>
	</material>
	<material name="red">
		<color rgba="1 0 0 1"/>
	</material>
	<material name="yellow">
		<color rgba="1 1 0 1"/>
	</material>
	<material name="orange">
		<color rgba="1 0.647 0 1"/>
	</material>
	<material name="green">
		<color rgba="0 1 0 1"/>
	</material>
	<material name="blue">
		<color rgba="0 0 1 1"/>
	</material>
	<material name="black">
		<color rgba="0 0 0 1"/>
	</material>

    <link name="world"/>

    <link name="base">
        <visual>
            <geometry>
                <mesh filename="meshes/visual/Base.stl" scale="0.006 0.006 0.006"/>
            </geometry>
            <material name="red"/>
            <origin xyz="0 0 0" rpy="1.570796 0 0"/> 
        </visual>
        <collision>
            <geometry>
                <mesh filename="meshes/collision/Base_collision.stl" scale="0.006 0.006 0.006"/>
            </geometry>
            <origin xyz="0 0 0" rpy="1.570796 0 0"/> 
        </collision>
        <inertial>
            <mass value="1.0"/>
            <origin xyz="0 0 1" rpy="0 0 0" />
            <inertia ixx="0.0027" iyy="0.0027" izz="0.005" ixy="0" ixz="0" iyz="0"/>
        </inertial>
    </link>

    <joint name="r_axis" type="revolute">
        <parent link="world"/>
        <child link="base"/>
        <origin xyz="0 0 0"	rpy="0 0 0"/>
        <axis xyz="0 0 1"/>
        <limit lower="0" upper="6.28318530718" effort="0" velocity="0.174533"/>
    </joint>

    <link name="arm_section_1">
            <visual>
                <geometry>
                    <mesh filename="meshes/visual/R_section.stl" scale="0.006 0.006 0.006"/>
                </geometry>
                <material name="orange"/>
                <origin xyz="0 0 0.012" rpy="1.570796 0 0" /> 
            </visual>
            <collision>
                <geometry>
                    <mesh filename="meshes/collision/R_section_collision.stl" scale="0.006 0.006 0.006"/>
                </geometry>
                <origin xyz="0 0 0.012" rpy="1.570796 0 0"/> 
            </collision>
            <!-- Check intertial values-->
            <inertial>
                <mass value="1.0"/>
                <origin xyz="0 0 1" rpy="0 0 0" />
                <inertia ixx="0.0027" iyy="0.0027" izz="0.005" ixy="0" ixz="0" iyz="0"/>
            </inertial>
    </link>

        <joint name="base_to_arm_section_1" type="fixed">
            <parent link="base"/>
            <child link="arm_section_1"/>
            <origin xyz="0 -0.012 0"	rpy="0 0 0"/>
        </joint>

<link name="arm_section_2">
		<visual>
			<geometry>
				<mesh filename="meshes/visual/A_section.stl" scale="0.006 0.006 0.006"/>
			</geometry>
            <material name="yellow"/>
			<origin xyz="0 0 -0.45" rpy="1.570796 0 -0.5"/> 
		</visual>
		<collision>
			<geometry>
				<mesh filename="meshes/collision/A_section_collision.stl" scale="0.005 0.005 0.005"/>
			</geometry>
			<origin xyz="0 0 -0.45" rpy="1.570796 0.05 -0.5"/> 
		</collision>
		<!-- Check intertial values-->
		<inertial>
			<mass value="1.0"/>
			<origin rpy="0 0 0" xyz="0 0 1"/>
			<inertia ixx="0.0027" iyy="0.0027" izz="0.005" ixy="0" ixz="0" iyz="0"/>
		</inertial>
	</link>

    <joint name="a_axis" type="revolute">
		<parent link="arm_section_1"/>
		<child link="arm_section_2"/>
		<origin xyz="0 0 0.45" rpy="0 0 0.5"/>
		<axis xyz="0 1 0"/>
		<limit lower="-0.77" upper="0.77" effort="0" velocity="0.174533"/>
	</joint>

    <link name="arm_section_3">
		<visual>
			<geometry>
				<mesh filename="meshes/visual/B_section.stl" scale="0.006 0.006 0.006"/>
			</geometry>
			<material name="green"/>
			<origin xyz="0.6 -0.2 -1.15" rpy="1.570796 0 -0.5"/> 
		</visual>
		<collision>
			<geometry>
				<mesh filename="meshes/collision/B_section_collision.stl" scale="0.005 0.005 0.005"/>
			</geometry>
			<origin xyz="0.6 -0.2 -1.15" rpy="1.570796 0 -0.5"/> 
		</collision>
		<!-- Check intertial values-->
		<inertial>
			<mass value="1.0"/>
			<origin rpy="0 0 0" xyz="0 0 1"/>
			<inertia ixx="0.0027" iyy="0.0027" izz="0.005" ixy="0" ixz="0" iyz="0"/>
		</inertial>
	</link>

    <joint name="b_axis" type="revolute">
		<parent link="arm_section_2"/>
		<child link="arm_section_3"/>
		<origin xyz="-0.6 0.2 0.7" rpy="0 0 0"/>
		<axis xyz="0 1 0"/>
		<limit lower="-0.6" upper="3.14" effort="0" velocity="0.174533"/>
	</joint>

	<link name="arm_section_4">
		<visual>
			<geometry>
				<mesh filename="meshes/visual/C_section.stl" scale="0.005 0.005 0.005"/>
			</geometry>
			<material name="blue"/>
			<origin xyz="1.05 -0.21 -0.5" rpy="1.570796 0 -0.5"/> 
		</visual>
		<collision>
			<geometry>
				<mesh filename="meshes/collision/C_section_collision.stl" scale="0.005 0.005 0.005"/>
			</geometry>
			<origin xyz="1.05 -0.21 -0.5" rpy="1.570796 0 -0.5"/> 
		</collision>
		<!-- Check intertial values-->
		<inertial>
			<mass value="1.0"/>
			<origin rpy="0 0 0" xyz="0 0 1"/>
			<inertia ixx="0.0027" iyy="0.0027" izz="0.005" ixy="0" ixz="0" iyz="0"/>
		</inertial>
	</link>

    <joint name="c_axis" type="revolute">
		<parent link="arm_section_3"/>
		<child link="arm_section_4"/>
		<origin xyz="-0.65 0 -0.55" rpy="0 0 0"/>
		<axis xyz="0 1 0"/>
		<limit lower="-0.6" upper="1.5" effort="0" velocity="0.174533"/>
	</joint>

</robot>